Workbook

Sheet Cover
B1: Signet Jewelers Limited (NYSE: SIG)
B2: Baseline Value-Based ERM Model - Case Assignment #3(a)
B4: Course | C4: Columbia University ERMC PS5900 Capstone, Fall 2026 - Case Assignment #3(a): Baseline value-based ERM model
B5: Team | C5: Case Team #2: Meher Jain, Zainab Razzaque, Stanley Weng, Jana Chamsi Bacha, Anderson Chan
B6: Deliverable date | C6: October 13, 2026 (due Monday, October 19, 2026, 11pm ET (day before Session 7))
B7: Model units | C7: $ millions to one decimal; rates to 0.1%; store counts in units; fiscal years end about January 31 (FY2026A = actual year ended January 31, 2026; FY2027-FY2036 = ten projected years).
B8: Valuation approach | C8: Profits released: each segment distributes 100% of net income to shareholders every year, so the simplified balance sheet is static, and segment value = NPV at the segment cost of equity of FY2027-FY2036 distributable cash flows plus the present value of terminal equity (= FY2036 shareholders' equity). Company value is the sum of the three segment values; the choice is justified because Signet's dividends plus buybacks have run at roughly 85-110% of underlying earnings (FY2026: $257M vs $294M net income; H1 FY2027: $197M vs about $84M).
B10: Model integrity status | C10: =IF(Checks!C38,"ALL CHECKS PASS","CHECK FAILURES - see Checks tab") -> ALL CHECKS PASS
B12: Colour legend
B13: Blue font | C13: Hard-coded input (assumption, FY2026A actual or snapshot)
B14: Black font | C14: Formula within the tab
B15: Green font | C15: Link to another tab
B16: Light-blue fill | C16: Section header; grey fill = sub-header; grey cells on the Total tab = intentionally blank assumptions
B18: Tab map
B19: Cover | C19: This page.
B20: Assumptions & Sources | C20: Every baseline assumption with value, rationale and APA source; reclassifications; questions for the lecturer/TAs; limitations; reference list.
B21: Model - NA | C21: North America segment: baseline assumptions -> shock -> scenario -> projection, valuation and balance sheet. North America reportable segment: Kay, Zales, Jared, Diamonds Direct, Banter by Piercing Pagoda, Rocksbox, the digital brands James Allen and Blue Nile, and Peoples Jewellers (Canada).
B22: Model - INTL | C22: International segment, identical layout. International reportable segment: H.Samuel and Ernest Jones stores and e-commerce in the UK and the Republic of Ireland.
B23: Model - OTHER | C23: Other / corporate, identical layout. 'Other' reportable segment (rough-diamond purchasing and polishing subsidiaries selling to third parties) plus corporate and unallocated costs. No stores, no e-commerce, no services: those rows are kept at zero.
B24: Total Company | C24: Same layout; assumptions blank; every financial line = sum of the three segments; EPS, ROE, payout and the actual-market-valuation check.
B25: Summary & Chart | C25: Segment value table, native chart 'Signet Baseline Company Value by Business Segment ($M)', sales/net income chart, sensitivity table.
B26: Checks | C26: Formula-driven TRUE/FALSE integrity checks feeding the status cell above.
B28: Row layout | C28: All four model tabs share one row layout: baseline assumptions rows 6-20, shocks rows 23-37, scenario rows 40-54, projection rows 58-112 (total sales row 70, operating income row 80, net income row 87, segment value rows 98-101, equity row 110). Risk tabs in 3(d) can therefore reference the same cells across segments.
B30: Reproducibility | C30: Generated by build/build_model.py (openpyxl); all inputs are in one dictionary at the top of that script with the source beside each. The workbook contains live Excel formulas only (no macros, no external links). Excel recalculates on open.

Sheet Assumptions & Sources
A1: Baseline assumptions, rationale and sources
A2: One row per assumption. Values are repeated in blue on the model tabs; this tab is documentation (no model formulas depend on it). APA 7th in-text citations; full reference list at the bottom.
A4: # | B4: Group | C4: Assumption | D4: Segment(s) | E4: Value(s) by year or rule | F4: Rationale | G4: Source (APA in-text)
A5: 1 | B5: Revenue drivers | C5: Store count roll-forward: gross openings | D5: NA | E5: FY27 6; FY28 10; FY29 10; FY30+ 12 per year | F5: Signet opened 14 stores in FY2026 and only 3 in H1 FY2027 while it reorients toward off-mall formats; openings recover modestly as repositioned stores open. | G5: Signet Jewelers Limited (2026a, 2026d)
A6: 2 | B6: Revenue drivers | C6: Store count roll-forward: closures | D6: NA | E6: FY27 70; FY28 50; FY29 40; FY30 30; FY31 25; FY32+ 20 | F6: 64 closures in FY2026 and 50 already in H1 FY2027; management guides to a low-single-digit decline in net square footage. Closures taper as the mall-heavy portion of the fleet shrinks. | G6: Signet Jewelers Limited (2026a, 2026c, 2026d)
A7: 3 | B7: Revenue drivers | C7: Store count roll-forward | D7: INTL | E7: Openings 2 per year; closures 4 (FY27), 5 (FY28-FY31), 4 thereafter | F7: International closed 10 stores in FY2026 and 3 in H1 FY2027 with 2 openings; a slow net reduction of the UK/ROI estate continues. | G7: Signet Jewelers Limited (2026a, 2026d)
A8: 4 | B8: Revenue drivers | C8: Store count roll-forward | D8: OTHER | E8: Zero stores, openings and closures | F8: The Other segment and corporate have no retail stores; rows kept at zero per the 'same layout' guideline. | G8: Signet Jewelers Limited (2026a)
A9: 5 | B9: Revenue drivers | C9: Same-store sales growth (sales per average store) | D9: NA | E9: FY27 1.5%; FY28+ 2.0% | F9: FY2026 NA same-store sales +1.2%, Q2 FY2027 +2.2%, FY2027 guidance flat to +2.5%. Long-run 2.0% is in line with FOMC PCE inflation of 2.1-2.3% and a mature, share-gaining retailer; consensus revenue growth is 1.2-1.6% a year after net closures. | G9: Signet Jewelers Limited (2026b, 2026c); Board of Governors of the Federal Reserve System (2026b); Yahoo Finance (2026)
A10: 6 | B10: Revenue drivers | C10: Same-store sales growth | D10: INTL | E10: 2.0% every year | F10: FY2026 International same-store sales +2.6% (5.3% constant-currency total growth); UK CPI about 3% in early 2027 falling toward 2%; IMF UK GDP 1.3-1.5%. | G10: Signet Jewelers Limited (2026b); International Monetary Fund (2026a); Vanguard (2026)
A11: 7 | B11: Revenue drivers | C11: E-commerce merchandise sales growth | D11: NA | E11: FY27 3.0%; FY28+ 4.0% | F11: E-commerce is 21.8% of sales. The digital brands (James Allen, Blue Nile, $481.5M) shrank and were impaired in FY2025-26 and are now stabilised under 'Grow Brand Love'; omnichannel growth of the store brands lifts the blended rate slightly above store growth. | G11: Signet Jewelers Limited (2026a, 2026f)
A12: 8 | B12: Revenue drivers | C12: E-commerce merchandise sales growth | D12: INTL | E12: 3.0% every year | F12: H.Samuel and Ernest Jones online growth assumed at nominal UK demand growth. | G12: Signet Jewelers Limited (2026a)
A13: 9 | B13: Revenue drivers | C13: Services attach rate (% of merchandise sales) | D13: NA / INTL | E13: NA 13.6% (FY26A) -> 13.8% (FY27) -> 14.0% (FY28+); INTL 11.1% flat | F13: Services revenue grew 7.8% to $803.5M in FY2026 on extended-service-plan strength while merchandise was flat, so attach rises modestly then stabilises. International attach set lower (less ESP penetration). | G13: Signet Jewelers Limited (2026a, 2026b)
A14: 10 | B14: Revenue drivers | C14: Other (diamond sourcing) revenue growth | D14: OTHER | E14: 2.0% every year | F14: Third-party rough/polished diamond sales ($39.6M) grow with inflation; natural-diamond price weakness caps upside. | G14: Signet Jewelers Limited (2026a)
A15: 11 | B15: Expense drivers | C15: Cost of sales % of total sales | D15: NA | E15: FY26A 59.8% -> 59.3% from FY27 | F15: Consolidated gross margin was 39.5% (39.2% FY25). The new Bread Financial credit agreement adds $30-40M of margin/non-comp revenue from FY2027 (about 0.5pp of NA sales); gold-cost and tariff headwinds assumed to offset the services mix benefit thereafter. | G15: Signet Jewelers Limited (2026a, 2026c); CNBC (2026)
A16: 12 | B16: Expense drivers | C16: Cost of sales % of total sales | D16: INTL | E16: 68.0% flat | F16: International gross margin estimated at 32% (FY2025 implied about 30% from segment SG&A of $103.1M and operating income of $1.0M incl. $7.8M one-offs); UK fashion/watch mix is lower-margin than NA bridal. | G16: Signet Jewelers Limited (2025a, 2026b)
... A34: 30 | B34: Valuation | C34: Profits released vs. profits retained | D34: All | E34: Profits released | F34: Dividends plus buybacks: FY2026 $257.1M vs net income $294.4M (87%); H1 FY2027 $196.7M vs about $84M; $125M ASR added. Distributing all earnings is the closer approximation of Signet's behaviour; equity roll-forward holds in every tab (Checks). | G34: Signet Jewelers Limited (2026b, 2026c, 2026d); Columbia University Capstone (2026a)
A36: Reclassifications and FY2026A calibration (how the 'Last Yr' column was built)
B37: Segment sales | C37: NA 6,363.6 = consolidated 6,813.6 less International 410.4 less Other 39.6 (search excerpt: 'about $6.36 billion, +1.0%').
B38: Segment cost of sales / SG&A | C38: Fiscal 2026 segment cost lines (Note 5 'significant segment expenses') could not be retrieved, so: INTL gross margin 32.0% (FY2025 implied about 30%), INTL SG&A 27.5% of sales (FY2025 27.6%), OTHER gross margin 8.0%, corporate fixed SG&A 56.0 (FY2025 54.8 grown about 2%), NA = residual. Segment operating income still ties exactly to reported figures (NA 452.6, INTL 16.3, OTHER -75.8). Replace with the 10-K table when available.
B39: Other operating income/(expense) | C39: Consolidated -128.3 (= operating income 393.1 - gross margin 2,694.6 + SG&A 2,173.2) comprises impairments (about 91.3 digital brands) and restructuring; split NA -103.3 / INTL -2.0 / OTHER -23.0 so that segment operating income ties.
B40: Revenue build (FY2026A) | C40: Services: NA 760.0 and INTL 41.0 of the 803.5 consolidated (balance assumed inside Other). E-commerce: 21.8% x 6,813.6 = 1,485.4, of which INTL 61.6 (15% of its sales) and NA 1,423.8. Store merchandise sales = segment sales - services - e-commerce; sales per store = store merchandise sales / average stores (NA 1.776, INTL 1.193).
B41: Interest, other non-operating and tax | C41: Net interest income 4.0 + other non-operating income 1.0 = 5.0 allocated by sales share (NA 4.7, INTL 0.3, OTHER 0.0). Income taxes 103.7 allocated at the 26.0% effective rate (NA 119.1, INTL 4.3, OTHER -19.7 tax benefit on the corporate loss).
B42: Balance sheet | C42: Simplified assets = cash 874.8 + inventory 1,940.1 = 2,814.9. Other liabilities, net = 2,814.9 - reported equity 1,966.2 = 848.7 (plug). All lines allocated by FY2026 sales share.
A44: Questions for the lecturer / TAs
B45: Q1 | C45: Segment structure: we model three tabs (NA, INTL, OTHER = diamond sourcing + corporate/unallocated) so the Total tab reproduces the consolidated statements exactly. OTHER has a negative value (corporate cost centre). Is this acceptable, or should corporate costs be allocated into NA and INTL?
B46: Q2 | C46: Valuation approach: we chose 'profits released' (PV of distributed earnings + PV of terminal equity) rather than 'profits retained'. Please confirm either is acceptable for 3(a) and that the same approach must be kept in 3(d).
B47: Q3 | C47: Balance-sheet simplification: equity is calibrated to reported shareholders' equity through a single 'other liabilities, net' plug. Is a book-equity terminal value preferred to a tangible-equity (ex-goodwill) terminal value?
B48: Q4 | C48: Segment cost allocations: the Fiscal 2026 segment cost-of-sales/SG&A table could not be retrieved in the build environment; allocations are documented above and will be replaced from the 10-K. Does the TA want the replacement before Session 7?
B49: Q5 | C49: Discount rate: single CAPM cost of equity per segment (10.5% / 12.0% / 10.5%) with the 10-year Treasury at 5.24%. Is a segment premium for International appropriate, or should one company-wide rate be used?
A51: Limitations
B52: L1 | C52: Data access: sec.gov, signetjewelers.com and the IR PDF host were blocked in the build environment, so figures come from web-search excerpts of the 10-K, the Q4 FY2026 and Q2 FY2027 releases and their verbatim re-publications. Confidence flags (A-D) are in data/*.csv. Segment cost lines, International adjusted operating income and intangibles were not retrievable.
B53: L2 | C53: Static balance sheet: no capex, depreciation, working-capital build or lease accounting; inventory and cash are held flat. Buybacks are treated as distributions and the share count is not reduced, so modelled EPS growth is slower than consensus.
B54: L3 | C54: FX: International is modelled in USD at FY2026 rates; a GBP shock would be applied through the INTL sales-per-store and e-commerce drivers in 3(d).
B55: L4 | C55: Seasonality: annual model; the holiday-quarter concentration of earnings is not visible (a quarterly layer could be added later).
B56: L5 | C56: Tax: a single effective rate per segment; OTHER's corporate loss generates a tax benefit, consistent with consolidated filing.
B57: L6 | C57: The 'Baseline snapshot' value is a pasted number (as in the Pear model) so that 3(d) can compare scenario runs against it; it is checked against the live value on the Checks tab and must be re-pasted if baseline assumptions change (rerun build/build_model.py).
A59: References (APA 7th)
B60: Bank of Canada. (2026, July 15). Monetary policy report: July 2026. https://www.bankofcanada.ca/publications/mpr/mpr-2026-07-15/projections/
B61: Board of Governors of the Federal Reserve System. (2026a, October 9). H.15 selected interest rates (daily). https://www.federalreserve.gov/releases/h15/
B62: Board of Governors of the Federal Reserve System. (2026b, September 16). Summary of economic projections. https://www.federalreserve.gov/monetarypolicy/fomcprojtabl20260916.htm
...

Sheet Model - NA
A1: Signet Jewelers - Baseline Value-Based ERM Model - Segment: North America
A2: North America reportable segment: Kay, Zales, Jared, Diamonds Direct, Banter by Piercing Pagoda, Rocksbox, the digital brands James Allen and Blue Nile, and Peoples Jewellers (Canada). Units: $ millions (one decimal) unless stated; fiscal years end about January 31 (FY2026 = year ended Jan 31, 2026). Blue = hard-coded input, black = formula, green = link to another tab.
A3: Section | B3: Line item | C3: Last Yr (FY2026A) | D3: FY2027 | E3: FY2028 | F3: FY2029 | G3: FY2030 | H3: FY2031 | I3: FY2032 | J3: FY2033 | K3: FY2034 | L3: FY2035 | M3: FY2036 | N3: Units | O3: Notes
A5: BASELINE ASSUMPTIONS (blue = hard-coded input; black '=previous cell' carries an assumption forward)
A6: Baseline | B6: Gross store openings (number of stores) | C6: =C59 -> 14 | D6: 6 | E6: 10 | F6: =E6 -> 10 | G6: 12 | H6: =G6 -> 12 | I6: =H6 -> 12 | J6: =I6 -> 12 | K6: =J6 -> 12 | L6: =K6 -> 12 | M6: =L6 -> 12 | N6: # stores | O6: Gross openings; net of closures drives average stores.
A7: Baseline | B7: Store closures (number of stores) | C7: =C60 -> 64 | D7: 70 | E7: 50 | F7: 40 | G7: 30 | H7: 25 | I7: 20 | J7: =I7 -> 20 | K7: =J7 -> 20 | L7: =K7 -> 20 | M7: =L7 -> 20 | N7: # stores | O7: Fleet optimisation: mall closures / off-mall repositioning (net sq ft 'low-single-digit decline' guidance).
A8: Baseline | B8: Same-store sales growth (applied to merchandise sales per average store) | C8: 0.012 | D8: 0.015 | E8: 0.02 | F8: =E8 -> 0.02 | G8: =F8 -> 0.02 | H8: =G8 -> 0.02 | I8: =H8 -> 0.02 | J8: =I8 -> 0.02 | K8: =J8 -> 0.02 | L8: =K8 -> 0.02 | M8: =L8 -> 0.02 | N8: % p.a. | O8: Price/mix + traffic growth applied to sales per average store.
A9: Baseline | B9: E-commerce merchandise sales growth | D9: 0.03 | E9: 0.04 | F9: =E9 -> 0.04 | G9: =F9 -> 0.04 | H9: =G9 -> 0.04 | I9: =H9 -> 0.04 | J9: =I9 -> 0.04 | K9: =J9 -> 0.04 | L9: =K9 -> 0.04 | M9: =L9 -> 0.04 | N9: % p.a. | O9: Includes digital-native brands (NA) and store-brand online sales.
A10: Baseline | B10: Services attach rate (services revenue as % of merchandise sales) | C10: =IF(C66+C67=0,0,C68/(C66+C67)) -> 0.1356271 | D10: 0.138 | E10: 0.14 | F10: =E10 -> 0.14 | G10: =F10 -> 0.14 | H10: =G10 -> 0.14 | I10: =H10 -> 0.14 | J10: =I10 -> 0.14 | K10: =J10 -> 0.14 | L10: =K10 -> 0.14 | M10: =L10 -> 0.14 | N10: % of merch. | O10: Extended service plans, repairs, custom design.
A11: Baseline | B11: Other (non-retail / diamond sourcing) revenue growth | D11: 0 | E11: =D11 -> 0 | F11: =E11 -> 0 | G11: =F11 -> 0 | H11: =G11 -> 0 | I11: =H11 -> 0 | J11: =I11 -> 0 | K11: =J11 -> 0 | L11: =K11 -> 0 | M11: =L11 -> 0 | N11: % p.a. | O11: Only the diamond-sourcing sales in OTHER are non-zero.
A12: Baseline | B12: Cost of sales (incl. store occupancy) as % of total sales | C12: =IF(C70=0,0,C72/C70) -> 0.59769627 | D12: 0.593 | E12: =D12 -> 0.593 | F12: =E12 -> 0.593 | G12: =F12 -> 0.593 | H12: =G12 -> 0.593 | I12: =H12 -> 0.593 | J12: =I12 -> 0.593 | K12: =J12 -> 0.593 | L12: =K12 -> 0.593 | M12: =L12 -> 0.593 | N12: % of sales | O12: Signet books store occupancy in cost of sales; 1 - this = gross margin %.
A13: Baseline | B13: Variable SG&A (store payroll, advertising, credit) as % of total sales | C13: =IF(C70=0,0,C75/C70) -> 0.19999686 | D13: 0.2 | E13: =D13 -> 0.2 | F13: =E13 -> 0.2 | G13: =F13 -> 0.2 | H13: =G13 -> 0.2 | I13: =H13 -> 0.2 | J13: =I13 -> 0.2 | K13: =J13 -> 0.2 | L13: =K13 -> 0.2 | M13: =L13 -> 0.2 | N13: % of sales | O13: Marginal expenses that move with sales.
A14: Baseline | B14: Fixed SG&A inflation (corporate, support, fixed store overhead) | D14: 0.025 | E14: 0.023 | F14: 0.021 | G14: 0.02 | H14: =G14 -> 0.02 | I14: =H14 -> 0.02 | J14: =I14 -> 0.02 | K14: =J14 -> 0.02 | L14: =K14 -> 0.02 | M14: =L14 -> 0.02 | N14: % p.a. | O14: Fixed expenses grow with inflation (Session 6 guidance).
A15: Baseline | B15: Cost-savings initiatives (incremental run-rate cut to fixed SG&A) | D15: 0 | E15: =D15 -> 0 | F15: =E15 -> 0 | G15: =F15 -> 0 | H15: =G15 -> 0 | I15: =H15 -> 0 | J15: =I15 -> 0 | K15: =J15 -> 0 | L15: =K15 -> 0 | M15: =L15 -> 0 | N15: $M | O15: Zero: no quantified cost-savings programme disclosed. Row kept for shocks.
A16: Baseline | B16: Other operating income / (expense), one-time items (+ = income) | C16: =C79 -> -103.3 | D16: 30 | E16: 0 | F16: =E16 -> 0 | G16: =F16 -> 0 | H16: =G16 -> 0 | I16: =H16 -> 0 | J16: =I16 -> 0 | K16: =J16 -> 0 | L16: =K16 -> 0 | M16: =L16 -> 0 | N16: $M | O16: FY2027 NA: +30 tariff refunds expected by management; impairments/restructuring assumed nil going forward.
A17: Baseline | B17: Net yield on invested assets (cash & equivalents) | D17: 0.007 | E17: =D17 -> 0.007 | F17: =E17 -> 0.007 | G17: =F17 -> 0.007 | H17: =G17 -> 0.007 | I17: =H17 -> 0.007 | J17: =I17 -> 0.007 | K17: =J17 -> 0.007 | L17: =K17 -> 0.007 | M17: =L17 -> 0.007 | N17: % of prior-yr cash | O17: Calibrated: reported net interest income was only 4.0 (FY26) and 9.8 (FY25) on 600-900 of cash.
A18: Baseline | B18: Interest rate on debt (ABL revolver; debt is zero in baseline) | D18: 0.065 | E18: =D18 -> 0.065 | F18: =E18 -> 0.065 | G18: =F18 -> 0.065 | H18: =G18 -> 0.065 | I18: =H18 -> 0.065 | J18: =I18 -> 0.065 | K18: =J18 -> 0.065 | L18: =K18 -> 0.065 | M18: =L18 -> 0.065 | N18: % of prior-yr debt | O18: No funded debt at FY2026A; rate kept for interest-rate / liquidity shocks.
A19: Baseline | B19: Effective income tax rate | C19: =IF(C84=0,0,C86/C84) -> 0.26044172 | D19: 0.24 | E19: =D19 -> 0.24 | F19: =E19 -> 0.24 | G19: =F19 -> 0.24 | H19: =G19 -> 0.24 | I19: =H19 -> 0.24 | J19: =I19 -> 0.24 | K19: =J19 -> 0.24 | L19: =K19 -> 0.24 | M19: =L19 -> 0.24 | N19: % of pre-tax | O19: FY2027 guidance 23-25% (NA/OTHER 24%); UK statutory 25% for INTL.
A20: Baseline | B20: Discount rate (cost of equity, CAPM) - single rate for the segment | D20: 0.105 | N20: % p.a. | O20: CAPM: 5.24% + 1.25 x 4.20% = 10.5%; INTL +1.5pp premium. Single rate in the FY2027 column (as in Pear).
A22: SHOCK TO ASSUMPTIONS - additive shocks, all ZERO in the baseline (for use in Assignment 3(d))
A23: Shock | B23: Shock: Gross store openings (number of stores) | D23: 0 | E23: 0 | F23: 0 | G23: 0 | H23: 0 | I23: 0 | J23: 0 | K23: 0 | L23: 0 | M23: 0 | N23: # stores
A24: Shock | B24: Shock: Store closures (number of stores) | D24: 0 | E24: 0 | F24: 0 | G24: 0 | H24: 0 | I24: 0 | J24: 0 | K24: 0 | L24: 0 | M24: 0 | N24: # stores
A25: Shock | B25: Shock: Same-store sales growth (applied to merchandise sales per average store) | D25: 0 | E25: 0 | F25: 0 | G25: 0 | H25: 0 | I25: 0 | J25: 0 | K25: 0 | L25: 0 | M25: 0 | N25: % p.a.
A26: Shock | B26: Shock: E-commerce merchandise sales growth | D26: 0 | E26: 0 | F26: 0 | G26: 0 | H26: 0 | I26: 0 | J26: 0 | K26: 0 | L26: 0 | M26: 0 | N26: % p.a.
A27: Shock | B27: Shock: Services attach rate (services revenue as % of merchandise sales) | D27: 0 | E27: 0 | F27: 0 | G27: 0 | H27: 0 | I27: 0 | J27: 0 | K27: 0 | L27: 0 | M27: 0 | N27: % of merch.
A28: Shock | B28: Shock: Other (non-retail / diamond sourcing) revenue growth | D28: 0 | E28: 0 | F28: 0 | G28: 0 | H28: 0 | I28: 0 | J28: 0 | K28: 0 | L28: 0 | M28: 0 | N28: % p.a.
A29: Shock | B29: Shock: Cost of sales (incl. store occupancy) as % of total sales | D29: 0 | E29: 0 | F29: 0 | G29: 0 | H29: 0 | I29: 0 | J29: 0 | K29: 0 | L29: 0 | M29: 0 | N29: % of sales
A30: Shock | B30: Shock: Variable SG&A (store payroll, advertising, credit) as % of total sales | D30: 0 | E30: 0 | F30: 0 | G30: 0 | H30: 0 | I30: 0 | J30: 0 | K30: 0 | L30: 0 | M30: 0 | N30: % of sales
A31: Shock | B31: Shock: Fixed SG&A inflation (corporate, support, fixed store overhead) | D31: 0 | E31: 0 | F31: 0 | G31: 0 | H31: 0 | I31: 0 | J31: 0 | K31: 0 | L31: 0 | M31: 0 | N31: % p.a.
A32: Shock | B32: Shock: Cost-savings initiatives (incremental run-rate cut to fixed SG&A) | D32: 0 | E32: 0 | F32: 0 | G32: 0 | H32: 0 | I32: 0 | J32: 0 | K32: 0 | L32: 0 | M32: 0 | N32: $M
A33: Shock | B33: Shock: Other operating income / (expense), one-time items (+ = income) | D33: 0 | E33: 0 | F33: 0 | G33: 0 | H33: 0 | I33: 0 | J33: 0 | K33: 0 | L33: 0 | M33: 0 | N33: $M
A34: Shock | B34: Shock: Net yield on invested assets (cash & equivalents) | D34: 0 | E34: 0 | F34: 0 | G34: 0 | H34: 0 | I34: 0 | J34: 0 | K34: 0 | L34: 0 | M34: 0 | N34: % of prior-yr cash
... A36: Shock | B36: Shock: Effective income tax rate | D36: 0 | E36: 0 | F36: 0 | G36: 0 | H36: 0 | I36: 0 | J36: 0 | K36: 0 | L36: 0 | M36: 0 | N36: % of pre-tax
A37: Shock | B37: Shock: Discount rate (cost of equity, CAPM) - single rate for the segment | D37: 0 | N37: % p.a.
A39: ASSUMPTIONS FOR SCENARIO RUN (every cell = baseline + shock; the projection reads ONLY this block)
A40: Scenario | B40: Scenario: Gross store openings (number of stores) | D40: =D6+D23 -> 6 | E40: =E6+E23 -> 10 | F40: =F6+F23 -> 10 | G40: =G6+G23 -> 12 | H40: =H6+H23 -> 12 | I40: =I6+I23 -> 12 | J40: =J6+J23 -> 12 | K40: =K6+K23 -> 12 | ... M40: =M6+M23 -> 12 | N40: # stores
A41: Scenario | B41: Scenario: Store closures (number of stores) | D41: =D7+D24 -> 70 | E41: =E7+E24 -> 50 | F41: =F7+F24 -> 40 | G41: =G7+G24 -> 30 | H41: =H7+H24 -> 25 | I41: =I7+I24 -> 20 | J41: =J7+J24 -> 20 | K41: =K7+K24 -> 20 | ... M41: =M7+M24 -> 20 | N41: # stores
A42: Scenario | B42: Scenario: Same-store sales growth (applied to merchandise sales per average store) | D42: =D8+D25 -> 0.015 | E42: =E8+E25 -> 0.02 | F42: =F8+F25 -> 0.02 | G42: =G8+G25 -> 0.02 | H42: =H8+H25 -> 0.02 | I42: =I8+I25 -> 0.02 | J42: =J8+J25 -> 0.02 | K42: =K8+K25 -> 0.02 | ... M42: =M8+M25 -> 0.02 | N42: % p.a.
A43: Scenario | B43: Scenario: E-commerce merchandise sales growth | D43: =D9+D26 -> 0.03 | E43: =E9+E26 -> 0.04 | F43: =F9+F26 -> 0.04 | G43: =G9+G26 -> 0.04 | H43: =H9+H26 -> 0.04 | I43: =I9+I26 -> 0.04 | J43: =J9+J26 -> 0.04 | K43: =K9+K26 -> 0.04 | ... M43: =M9+M26 -> 0.04 | N43: % p.a.
A44: Scenario | B44: Scenario: Services attach rate (services revenue as % of merchandise sales) | D44: =D10+D27 -> 0.138 | E44: =E10+E27 -> 0.14 | F44: =F10+F27 -> 0.14 | G44: =G10+G27 -> 0.14 | H44: =H10+H27 -> 0.14 | I44: =I10+I27 -> 0.14 | J44: =J10+J27 -> 0.14 | K44: =K10+K27 -> 0.14 | ... M44: =M10+M27 -> 0.14 | N44: % of merch.
...

Sheet Model - INTL
A1: Signet Jewelers - Baseline Value-Based ERM Model - Segment: International
A2: International reportable segment: H.Samuel and Ernest Jones stores and e-commerce in the UK and the Republic of Ireland. Units: $ millions (one decimal) unless stated; fiscal years end about January 31 (FY2026 = year ended Jan 31, 2026). Blue = hard-coded input, black = formula, green = link to another tab.
A3: Section | B3: Line item | C3: Last Yr (FY2026A) | D3: FY2027 | E3: FY2028 | F3: FY2029 | G3: FY2030 | H3: FY2031 | I3: FY2032 | J3: FY2033 | K3: FY2034 | L3: FY2035 | M3: FY2036 | N3: Units | O3: Notes
A5: BASELINE ASSUMPTIONS (blue = hard-coded input; black '=previous cell' carries an assumption forward)
A6: Baseline | B6: Gross store openings (number of stores) | C6: =C59 -> 0 | D6: 2 | E6: =D6 -> 2 | F6: =E6 -> 2 | G6: =F6 -> 2 | H6: =G6 -> 2 | I6: =H6 -> 2 | J6: =I6 -> 2 | K6: =J6 -> 2 | L6: =K6 -> 2 | M6: =L6 -> 2 | N6: # stores | O6: Gross openings; net of closures drives average stores.
A7: Baseline | B7: Store closures (number of stores) | C7: =C60 -> 10 | D7: 4 | E7: 5 | F7: =E7 -> 5 | G7: =F7 -> 5 | H7: =G7 -> 5 | I7: 4 | J7: =I7 -> 4 | K7: =J7 -> 4 | L7: =K7 -> 4 | M7: =L7 -> 4 | N7: # stores | O7: Fleet optimisation: mall closures / off-mall repositioning (net sq ft 'low-single-digit decline' guidance).
A8: Baseline | B8: Same-store sales growth (applied to merchandise sales per average store) | C8: 0.026 | D8: 0.02 | E8: =D8 -> 0.02 | F8: =E8 -> 0.02 | G8: =F8 -> 0.02 | H8: =G8 -> 0.02 | I8: =H8 -> 0.02 | J8: =I8 -> 0.02 | K8: =J8 -> 0.02 | L8: =K8 -> 0.02 | M8: =L8 -> 0.02 | N8: % p.a. | O8: Price/mix + traffic growth applied to sales per average store.
A9: Baseline | B9: E-commerce merchandise sales growth | D9: 0.03 | E9: =D9 -> 0.03 | F9: =E9 -> 0.03 | G9: =F9 -> 0.03 | H9: =G9 -> 0.03 | I9: =H9 -> 0.03 | J9: =I9 -> 0.03 | K9: =J9 -> 0.03 | L9: =K9 -> 0.03 | M9: =L9 -> 0.03 | N9: % p.a. | O9: Includes digital-native brands (NA) and store-brand online sales.
A10: Baseline | B10: Services attach rate (services revenue as % of merchandise sales) | C10: =IF(C66+C67=0,0,C68/(C66+C67)) -> 0.1109908 | D10: 0.111 | E10: =D10 -> 0.111 | F10: =E10 -> 0.111 | G10: =F10 -> 0.111 | H10: =G10 -> 0.111 | I10: =H10 -> 0.111 | J10: =I10 -> 0.111 | K10: =J10 -> 0.111 | L10: =K10 -> 0.111 | M10: =L10 -> 0.111 | N10: % of merch. | O10: Extended service plans, repairs, custom design.
A11: Baseline | B11: Other (non-retail / diamond sourcing) revenue growth | D11: 0 | E11: =D11 -> 0 | F11: =E11 -> 0 | G11: =F11 -> 0 | H11: =G11 -> 0 | I11: =H11 -> 0 | J11: =I11 -> 0 | K11: =J11 -> 0 | L11: =K11 -> 0 | M11: =L11 -> 0 | N11: % p.a. | O11: Only the diamond-sourcing sales in OTHER are non-zero.
A12: Baseline | B12: Cost of sales (incl. store occupancy) as % of total sales | C12: =IF(C70=0,0,C72/C70) -> 0.68006823 | D12: 0.68 | E12: =D12 -> 0.68 | F12: =E12 -> 0.68 | G12: =F12 -> 0.68 | H12: =G12 -> 0.68 | I12: =H12 -> 0.68 | J12: =I12 -> 0.68 | K12: =J12 -> 0.68 | L12: =K12 -> 0.68 | M12: =L12 -> 0.68 | N12: % of sales | O12: Signet books store occupancy in cost of sales; 1 - this = gross margin %.
A13: Baseline | B13: Variable SG&A (store payroll, advertising, credit) as % of total sales | C13: =IF(C70=0,0,C75/C70) -> 0.15009747 | D13: 0.15 | E13: =D13 -> 0.15 | F13: =E13 -> 0.15 | G13: =F13 -> 0.15 | H13: =G13 -> 0.15 | I13: =H13 -> 0.15 | J13: =I13 -> 0.15 | K13: =J13 -> 0.15 | L13: =K13 -> 0.15 | M13: =L13 -> 0.15 | N13: % of sales | O13: Marginal expenses that move with sales.
A14: Baseline | B14: Fixed SG&A inflation (corporate, support, fixed store overhead) | D14: 0.03 | E14: 0.025 | F14: 0.02 | G14: =F14 -> 0.02 | H14: =G14 -> 0.02 | I14: =H14 -> 0.02 | J14: =I14 -> 0.02 | K14: =J14 -> 0.02 | L14: =K14 -> 0.02 | M14: =L14 -> 0.02 | N14: % p.a. | O14: Fixed expenses grow with inflation (Session 6 guidance).
A15: Baseline | B15: Cost-savings initiatives (incremental run-rate cut to fixed SG&A) | D15: 0 | E15: =D15 -> 0 | F15: =E15 -> 0 | G15: =F15 -> 0 | H15: =G15 -> 0 | I15: =H15 -> 0 | J15: =I15 -> 0 | K15: =J15 -> 0 | L15: =K15 -> 0 | M15: =L15 -> 0 | N15: $M | O15: Zero: no quantified cost-savings programme disclosed. Row kept for shocks.
A16: Baseline | B16: Other operating income / (expense), one-time items (+ = income) | C16: =C79 -> -2 | D16: 0 | E16: =D16 -> 0 | F16: =E16 -> 0 | G16: =F16 -> 0 | H16: =G16 -> 0 | I16: =H16 -> 0 | J16: =I16 -> 0 | K16: =J16 -> 0 | L16: =K16 -> 0 | M16: =L16 -> 0 | N16: $M | O16: FY2027 NA: +30 tariff refunds expected by management; impairments/restructuring assumed nil going forward.
A17: Baseline | B17: Net yield on invested assets (cash & equivalents) | D17: 0.007 | E17: =D17 -> 0.007 | F17: =E17 -> 0.007 | G17: =F17 -> 0.007 | H17: =G17 -> 0.007 | I17: =H17 -> 0.007 | J17: =I17 -> 0.007 | K17: =J17 -> 0.007 | L17: =K17 -> 0.007 | M17: =L17 -> 0.007 | N17: % of prior-yr cash | O17: Calibrated: reported net interest income was only 4.0 (FY26) and 9.8 (FY25) on 600-900 of cash.
A18: Baseline | B18: Interest rate on debt (ABL revolver; debt is zero in baseline) | D18: 0.065 | E18: =D18 -> 0.065 | F18: =E18 -> 0.065 | G18: =F18 -> 0.065 | H18: =G18 -> 0.065 | I18: =H18 -> 0.065 | J18: =I18 -> 0.065 | K18: =J18 -> 0.065 | L18: =K18 -> 0.065 | M18: =L18 -> 0.065 | N18: % of prior-yr debt | O18: No funded debt at FY2026A; rate kept for interest-rate / liquidity shocks.
A19: Baseline | B19: Effective income tax rate | C19: =IF(C84=0,0,C86/C84) -> 0.25903614 | D19: 0.25 | E19: =D19 -> 0.25 | F19: =E19 -> 0.25 | G19: =F19 -> 0.25 | H19: =G19 -> 0.25 | I19: =H19 -> 0.25 | J19: =I19 -> 0.25 | K19: =J19 -> 0.25 | L19: =K19 -> 0.25 | M19: =L19 -> 0.25 | N19: % of pre-tax | O19: FY2027 guidance 23-25% (NA/OTHER 24%); UK statutory 25% for INTL.
A20: Baseline | B20: Discount rate (cost of equity, CAPM) - single rate for the segment | D20: 0.12 | N20: % p.a. | O20: CAPM: 5.24% + 1.25 x 4.20% = 10.5%; INTL +1.5pp premium. Single rate in the FY2027 column (as in Pear).
A22: SHOCK TO ASSUMPTIONS - additive shocks, all ZERO in the baseline (for use in Assignment 3(d))
A23: Shock | B23: Shock: Gross store openings (number of stores) | D23: 0 | E23: 0 | F23: 0 | G23: 0 | H23: 0 | I23: 0 | J23: 0 | K23: 0 | L23: 0 | M23: 0 | N23: # stores
A24: Shock | B24: Shock: Store closures (number of stores) | D24: 0 | E24: 0 | F24: 0 | G24: 0 | H24: 0 | I24: 0 | J24: 0 | K24: 0 | L24: 0 | M24: 0 | N24: # stores
A25: Shock | B25: Shock: Same-store sales growth (applied to merchandise sales per average store) | D25: 0 | E25: 0 | F25: 0 | G25: 0 | H25: 0 | I25: 0 | J25: 0 | K25: 0 | L25: 0 | M25: 0 | N25: % p.a.
A26: Shock | B26: Shock: E-commerce merchandise sales growth | D26: 0 | E26: 0 | F26: 0 | G26: 0 | H26: 0 | I26: 0 | J26: 0 | K26: 0 | L26: 0 | M26: 0 | N26: % p.a.
A27: Shock | B27: Shock: Services attach rate (services revenue as % of merchandise sales) | D27: 0 | E27: 0 | F27: 0 | G27: 0 | H27: 0 | I27: 0 | J27: 0 | K27: 0 | L27: 0 | M27: 0 | N27: % of merch.
A28: Shock | B28: Shock: Other (non-retail / diamond sourcing) revenue growth | D28: 0 | E28: 0 | F28: 0 | G28: 0 | H28: 0 | I28: 0 | J28: 0 | K28: 0 | L28: 0 | M28: 0 | N28: % p.a.
A29: Shock | B29: Shock: Cost of sales (incl. store occupancy) as % of total sales | D29: 0 | E29: 0 | F29: 0 | G29: 0 | H29: 0 | I29: 0 | J29: 0 | K29: 0 | L29: 0 | M29: 0 | N29: % of sales
A30: Shock | B30: Shock: Variable SG&A (store payroll, advertising, credit) as % of total sales | D30: 0 | E30: 0 | F30: 0 | G30: 0 | H30: 0 | I30: 0 | J30: 0 | K30: 0 | L30: 0 | M30: 0 | N30: % of sales
A31: Shock | B31: Shock: Fixed SG&A inflation (corporate, support, fixed store overhead) | D31: 0 | E31: 0 | F31: 0 | G31: 0 | H31: 0 | I31: 0 | J31: 0 | K31: 0 | L31: 0 | M31: 0 | N31: % p.a.
A32: Shock | B32: Shock: Cost-savings initiatives (incremental run-rate cut to fixed SG&A) | D32: 0 | E32: 0 | F32: 0 | G32: 0 | H32: 0 | I32: 0 | J32: 0 | K32: 0 | L32: 0 | M32: 0 | N32: $M
A33: Shock | B33: Shock: Other operating income / (expense), one-time items (+ = income) | D33: 0 | E33: 0 | F33: 0 | G33: 0 | H33: 0 | I33: 0 | J33: 0 | K33: 0 | L33: 0 | M33: 0 | N33: $M
A34: Shock | B34: Shock: Net yield on invested assets (cash & equivalents) | D34: 0 | E34: 0 | F34: 0 | G34: 0 | H34: 0 | I34: 0 | J34: 0 | K34: 0 | L34: 0 | M34: 0 | N34: % of prior-yr cash
... A36: Shock | B36: Shock: Effective income tax rate | D36: 0 | E36: 0 | F36: 0 | G36: 0 | H36: 0 | I36: 0 | J36: 0 | K36: 0 | L36: 0 | M36: 0 | N36: % of pre-tax
A37: Shock | B37: Shock: Discount rate (cost of equity, CAPM) - single rate for the segment | D37: 0 | N37: % p.a.
A39: ASSUMPTIONS FOR SCENARIO RUN (every cell = baseline + shock; the projection reads ONLY this block)
A40: Scenario | B40: Scenario: Gross store openings (number of stores) | D40: =D6+D23 -> 2 | E40: =E6+E23 -> 2 | F40: =F6+F23 -> 2 | G40: =G6+G23 -> 2 | H40: =H6+H23 -> 2 | I40: =I6+I23 -> 2 | J40: =J6+J23 -> 2 | K40: =K6+K23 -> 2 | ... M40: =M6+M23 -> 2 | N40: # stores
A41: Scenario | B41: Scenario: Store closures (number of stores) | D41: =D7+D24 -> 4 | E41: =E7+E24 -> 5 | F41: =F7+F24 -> 5 | G41: =G7+G24 -> 5 | H41: =H7+H24 -> 5 | I41: =I7+I24 -> 4 | J41: =J7+J24 -> 4 | K41: =K7+K24 -> 4 | ... M41: =M7+M24 -> 4 | N41: # stores
A42: Scenario | B42: Scenario: Same-store sales growth (applied to merchandise sales per average store) | D42: =D8+D25 -> 0.02 | E42: =E8+E25 -> 0.02 | F42: =F8+F25 -> 0.02 | G42: =G8+G25 -> 0.02 | H42: =H8+H25 -> 0.02 | I42: =I8+I25 -> 0.02 | J42: =J8+J25 -> 0.02 | K42: =K8+K25 -> 0.02 | ... M42: =M8+M25 -> 0.02 | N42: % p.a.
A43: Scenario | B43: Scenario: E-commerce merchandise sales growth | D43: =D9+D26 -> 0.03 | E43: =E9+E26 -> 0.03 | F43: =F9+F26 -> 0.03 | G43: =G9+G26 -> 0.03 | H43: =H9+H26 -> 0.03 | I43: =I9+I26 -> 0.03 | J43: =J9+J26 -> 0.03 | K43: =K9+K26 -> 0.03 | ... M43: =M9+M26 -> 0.03 | N43: % p.a.
A44: Scenario | B44: Scenario: Services attach rate (services revenue as % of merchandise sales) | D44: =D10+D27 -> 0.111 | E44: =E10+E27 -> 0.111 | F44: =F10+F27 -> 0.111 | G44: =G10+G27 -> 0.111 | H44: =H10+H27 -> 0.111 | I44: =I10+I27 -> 0.111 | J44: =J10+J27 -> 0.111 | K44: =K10+K27 -> 0.111 | ... M44: =M10+M27 -> 0.111 | N44: % of merch.
...

Sheet Model - OTHER
A1: Signet Jewelers - Baseline Value-Based ERM Model - Segment: Other / Corporate
A2: 'Other' reportable segment (rough-diamond purchasing and polishing subsidiaries selling to third parties) plus corporate and unallocated costs. No stores, no e-commerce, no services: those rows are kept at zero. Units: $ millions (one decimal) unless stated; fiscal years end about January 31 (FY2026 = year ended Jan 31, 2026). Blue = hard-coded input, black = formula, green = link to another tab.
A3: Section | B3: Line item | C3: Last Yr (FY2026A) | D3: FY2027 | E3: FY2028 | F3: FY2029 | G3: FY2030 | H3: FY2031 | I3: FY2032 | J3: FY2033 | K3: FY2034 | L3: FY2035 | M3: FY2036 | N3: Units | O3: Notes
A5: BASELINE ASSUMPTIONS (blue = hard-coded input; black '=previous cell' carries an assumption forward)
A6: Baseline | B6: Gross store openings (number of stores) | C6: =C59 -> 0 | D6: 0 | E6: =D6 -> 0 | F6: =E6 -> 0 | G6: =F6 -> 0 | H6: =G6 -> 0 | I6: =H6 -> 0 | J6: =I6 -> 0 | K6: =J6 -> 0 | L6: =K6 -> 0 | M6: =L6 -> 0 | N6: # stores | O6: Gross openings; net of closures drives average stores.
A7: Baseline | B7: Store closures (number of stores) | C7: =C60 -> 0 | D7: 0 | E7: =D7 -> 0 | F7: =E7 -> 0 | G7: =F7 -> 0 | H7: =G7 -> 0 | I7: =H7 -> 0 | J7: =I7 -> 0 | K7: =J7 -> 0 | L7: =K7 -> 0 | M7: =L7 -> 0 | N7: # stores | O7: Fleet optimisation: mall closures / off-mall repositioning (net sq ft 'low-single-digit decline' guidance).
A8: Baseline | B8: Same-store sales growth (applied to merchandise sales per average store) | D8: 0 | E8: =D8 -> 0 | F8: =E8 -> 0 | G8: =F8 -> 0 | H8: =G8 -> 0 | I8: =H8 -> 0 | J8: =I8 -> 0 | K8: =J8 -> 0 | L8: =K8 -> 0 | M8: =L8 -> 0 | N8: % p.a. | O8: Price/mix + traffic growth applied to sales per average store.
A9: Baseline | B9: E-commerce merchandise sales growth | D9: 0 | E9: =D9 -> 0 | F9: =E9 -> 0 | G9: =F9 -> 0 | H9: =G9 -> 0 | I9: =H9 -> 0 | J9: =I9 -> 0 | K9: =J9 -> 0 | L9: =K9 -> 0 | M9: =L9 -> 0 | N9: % p.a. | O9: Includes digital-native brands (NA) and store-brand online sales.
A10: Baseline | B10: Services attach rate (services revenue as % of merchandise sales) | C10: =IF(C66+C67=0,0,C68/(C66+C67)) -> 0 | D10: 0 | E10: =D10 -> 0 | F10: =E10 -> 0 | G10: =F10 -> 0 | H10: =G10 -> 0 | I10: =H10 -> 0 | J10: =I10 -> 0 | K10: =J10 -> 0 | L10: =K10 -> 0 | M10: =L10 -> 0 | N10: % of merch. | O10: Extended service plans, repairs, custom design.
A11: Baseline | B11: Other (non-retail / diamond sourcing) revenue growth | D11: 0.02 | E11: =D11 -> 0.02 | F11: =E11 -> 0.02 | G11: =F11 -> 0.02 | H11: =G11 -> 0.02 | I11: =H11 -> 0.02 | J11: =I11 -> 0.02 | K11: =J11 -> 0.02 | L11: =K11 -> 0.02 | M11: =L11 -> 0.02 | N11: % p.a. | O11: Only the diamond-sourcing sales in OTHER are non-zero.
A12: Baseline | B12: Cost of sales (incl. store occupancy) as % of total sales | C12: =IF(C70=0,0,C72/C70) -> 0.91919192 | D12: 0.92 | E12: =D12 -> 0.92 | F12: =E12 -> 0.92 | G12: =F12 -> 0.92 | H12: =G12 -> 0.92 | I12: =H12 -> 0.92 | J12: =I12 -> 0.92 | K12: =J12 -> 0.92 | L12: =K12 -> 0.92 | M12: =L12 -> 0.92 | N12: % of sales | O12: Signet books store occupancy in cost of sales; 1 - this = gross margin %.
A13: Baseline | B13: Variable SG&A (store payroll, advertising, credit) as % of total sales | C13: =IF(C70=0,0,C75/C70) -> 0 | D13: 0 | E13: =D13 -> 0 | F13: =E13 -> 0 | G13: =F13 -> 0 | H13: =G13 -> 0 | I13: =H13 -> 0 | J13: =I13 -> 0 | K13: =J13 -> 0 | L13: =K13 -> 0 | M13: =L13 -> 0 | N13: % of sales | O13: Marginal expenses that move with sales.
A14: Baseline | B14: Fixed SG&A inflation (corporate, support, fixed store overhead) | D14: 0.025 | E14: 0.023 | F14: 0.021 | G14: 0.02 | H14: =G14 -> 0.02 | I14: =H14 -> 0.02 | J14: =I14 -> 0.02 | K14: =J14 -> 0.02 | L14: =K14 -> 0.02 | M14: =L14 -> 0.02 | N14: % p.a. | O14: Fixed expenses grow with inflation (Session 6 guidance).
A15: Baseline | B15: Cost-savings initiatives (incremental run-rate cut to fixed SG&A) | D15: 0 | E15: =D15 -> 0 | F15: =E15 -> 0 | G15: =F15 -> 0 | H15: =G15 -> 0 | I15: =H15 -> 0 | J15: =I15 -> 0 | K15: =J15 -> 0 | L15: =K15 -> 0 | M15: =L15 -> 0 | N15: $M | O15: Zero: no quantified cost-savings programme disclosed. Row kept for shocks.
A16: Baseline | B16: Other operating income / (expense), one-time items (+ = income) | C16: =C79 -> -23 | D16: 0 | E16: =D16 -> 0 | F16: =E16 -> 0 | G16: =F16 -> 0 | H16: =G16 -> 0 | I16: =H16 -> 0 | J16: =I16 -> 0 | K16: =J16 -> 0 | L16: =K16 -> 0 | M16: =L16 -> 0 | N16: $M | O16: FY2027 NA: +30 tariff refunds expected by management; impairments/restructuring assumed nil going forward.
A17: Baseline | B17: Net yield on invested assets (cash & equivalents) | D17: 0.007 | E17: =D17 -> 0.007 | F17: =E17 -> 0.007 | G17: =F17 -> 0.007 | H17: =G17 -> 0.007 | I17: =H17 -> 0.007 | J17: =I17 -> 0.007 | K17: =J17 -> 0.007 | L17: =K17 -> 0.007 | M17: =L17 -> 0.007 | N17: % of prior-yr cash | O17: Calibrated: reported net interest income was only 4.0 (FY26) and 9.8 (FY25) on 600-900 of cash.
A18: Baseline | B18: Interest rate on debt (ABL revolver; debt is zero in baseline) | D18: 0.065 | E18: =D18 -> 0.065 | F18: =E18 -> 0.065 | G18: =F18 -> 0.065 | H18: =G18 -> 0.065 | I18: =H18 -> 0.065 | J18: =I18 -> 0.065 | K18: =J18 -> 0.065 | L18: =K18 -> 0.065 | M18: =L18 -> 0.065 | N18: % of prior-yr debt | O18: No funded debt at FY2026A; rate kept for interest-rate / liquidity shocks.
A19: Baseline | B19: Effective income tax rate | C19: =IF(C84=0,0,C86/C84) -> 0.25989446 | D19: 0.24 | E19: =D19 -> 0.24 | F19: =E19 -> 0.24 | G19: =F19 -> 0.24 | H19: =G19 -> 0.24 | I19: =H19 -> 0.24 | J19: =I19 -> 0.24 | K19: =J19 -> 0.24 | L19: =K19 -> 0.24 | M19: =L19 -> 0.24 | N19: % of pre-tax | O19: FY2027 guidance 23-25% (NA/OTHER 24%); UK statutory 25% for INTL.
A20: Baseline | B20: Discount rate (cost of equity, CAPM) - single rate for the segment | D20: 0.105 | N20: % p.a. | O20: CAPM: 5.24% + 1.25 x 4.20% = 10.5%; INTL +1.5pp premium. Single rate in the FY2027 column (as in Pear).
A22: SHOCK TO ASSUMPTIONS - additive shocks, all ZERO in the baseline (for use in Assignment 3(d))
A23: Shock | B23: Shock: Gross store openings (number of stores) | D23: 0 | E23: 0 | F23: 0 | G23: 0 | H23: 0 | I23: 0 | J23: 0 | K23: 0 | L23: 0 | M23: 0 | N23: # stores
A24: Shock | B24: Shock: Store closures (number of stores) | D24: 0 | E24: 0 | F24: 0 | G24: 0 | H24: 0 | I24: 0 | J24: 0 | K24: 0 | L24: 0 | M24: 0 | N24: # stores
A25: Shock | B25: Shock: Same-store sales growth (applied to merchandise sales per average store) | D25: 0 | E25: 0 | F25: 0 | G25: 0 | H25: 0 | I25: 0 | J25: 0 | K25: 0 | L25: 0 | M25: 0 | N25: % p.a.
A26: Shock | B26: Shock: E-commerce merchandise sales growth | D26: 0 | E26: 0 | F26: 0 | G26: 0 | H26: 0 | I26: 0 | J26: 0 | K26: 0 | L26: 0 | M26: 0 | N26: % p.a.
A27: Shock | B27: Shock: Services attach rate (services revenue as % of merchandise sales) | D27: 0 | E27: 0 | F27: 0 | G27: 0 | H27: 0 | I27: 0 | J27: 0 | K27: 0 | L27: 0 | M27: 0 | N27: % of merch.
A28: Shock | B28: Shock: Other (non-retail / diamond sourcing) revenue growth | D28: 0 | E28: 0 | F28: 0 | G28: 0 | H28: 0 | I28: 0 | J28: 0 | K28: 0 | L28: 0 | M28: 0 | N28: % p.a.
A29: Shock | B29: Shock: Cost of sales (incl. store occupancy) as % of total sales | D29: 0 | E29: 0 | F29: 0 | G29: 0 | H29: 0 | I29: 0 | J29: 0 | K29: 0 | L29: 0 | M29: 0 | N29: % of sales
A30: Shock | B30: Shock: Variable SG&A (store payroll, advertising, credit) as % of total sales | D30: 0 | E30: 0 | F30: 0 | G30: 0 | H30: 0 | I30: 0 | J30: 0 | K30: 0 | L30: 0 | M30: 0 | N30: % of sales
A31: Shock | B31: Shock: Fixed SG&A inflation (corporate, support, fixed store overhead) | D31: 0 | E31: 0 | F31: 0 | G31: 0 | H31: 0 | I31: 0 | J31: 0 | K31: 0 | L31: 0 | M31: 0 | N31: % p.a.
A32: Shock | B32: Shock: Cost-savings initiatives (incremental run-rate cut to fixed SG&A) | D32: 0 | E32: 0 | F32: 0 | G32: 0 | H32: 0 | I32: 0 | J32: 0 | K32: 0 | L32: 0 | M32: 0 | N32: $M
A33: Shock | B33: Shock: Other operating income / (expense), one-time items (+ = income) | D33: 0 | E33: 0 | F33: 0 | G33: 0 | H33: 0 | I33: 0 | J33: 0 | K33: 0 | L33: 0 | M33: 0 | N33: $M
A34: Shock | B34: Shock: Net yield on invested assets (cash & equivalents) | D34: 0 | E34: 0 | F34: 0 | G34: 0 | H34: 0 | I34: 0 | J34: 0 | K34: 0 | L34: 0 | M34: 0 | N34: % of prior-yr cash
... A36: Shock | B36: Shock: Effective income tax rate | D36: 0 | E36: 0 | F36: 0 | G36: 0 | H36: 0 | I36: 0 | J36: 0 | K36: 0 | L36: 0 | M36: 0 | N36: % of pre-tax
A37: Shock | B37: Shock: Discount rate (cost of equity, CAPM) - single rate for the segment | D37: 0 | N37: % p.a.
A39: ASSUMPTIONS FOR SCENARIO RUN (every cell = baseline + shock; the projection reads ONLY this block)
A40: Scenario | B40: Scenario: Gross store openings (number of stores) | D40: =D6+D23 -> 0 | E40: =E6+E23 -> 0 | F40: =F6+F23 -> 0 | G40: =G6+G23 -> 0 | H40: =H6+H23 -> 0 | I40: =I6+I23 -> 0 | J40: =J6+J23 -> 0 | K40: =K6+K23 -> 0 | ... M40: =M6+M23 -> 0 | N40: # stores
A41: Scenario | B41: Scenario: Store closures (number of stores) | D41: =D7+D24 -> 0 | E41: =E7+E24 -> 0 | F41: =F7+F24 -> 0 | G41: =G7+G24 -> 0 | H41: =H7+H24 -> 0 | I41: =I7+I24 -> 0 | J41: =J7+J24 -> 0 | K41: =K7+K24 -> 0 | ... M41: =M7+M24 -> 0 | N41: # stores
A42: Scenario | B42: Scenario: Same-store sales growth (applied to merchandise sales per average store) | D42: =D8+D25 -> 0 | E42: =E8+E25 -> 0 | F42: =F8+F25 -> 0 | G42: =G8+G25 -> 0 | H42: =H8+H25 -> 0 | I42: =I8+I25 -> 0 | J42: =J8+J25 -> 0 | K42: =K8+K25 -> 0 | ... M42: =M8+M25 -> 0 | N42: % p.a.
A43: Scenario | B43: Scenario: E-commerce merchandise sales growth | D43: =D9+D26 -> 0 | E43: =E9+E26 -> 0 | F43: =F9+F26 -> 0 | G43: =G9+G26 -> 0 | H43: =H9+H26 -> 0 | I43: =I9+I26 -> 0 | J43: =J9+J26 -> 0 | K43: =K9+K26 -> 0 | ... M43: =M9+M26 -> 0 | N43: % p.a.
A44: Scenario | B44: Scenario: Services attach rate (services revenue as % of merchandise sales) | D44: =D10+D27 -> 0 | E44: =E10+E27 -> 0 | F44: =F10+F27 -> 0 | G44: =G10+G27 -> 0 | H44: =H10+H27 -> 0 | I44: =I10+I27 -> 0 | J44: =J10+J27 -> 0 | K44: =K10+K27 -> 0 | ... M44: =M10+M27 -> 0 | N44: % of merch.
...

Sheet Total Company
A1: Signet Jewelers - Baseline Value-Based ERM Model - TOTAL COMPANY (sum of Model - NA, Model - INTL, Model - OTHER)
A2: Same layout as the segment tabs. The three assumption blocks are intentionally blank: assumptions are applied at the business-segment level. Every financial-statement line is the sum of the three segment tabs (green); ratios and key metrics are recomputed here at the total-company level.
A3: Section | B3: Line item | C3: Last Yr (FY2026A) | D3: FY2027 | E3: FY2028 | F3: FY2029 | G3: FY2030 | H3: FY2031 | I3: FY2032 | J3: FY2033 | K3: FY2034 | L3: FY2035 | M3: FY2036 | N3: Units | O3: Notes
A5: BASELINE ASSUMPTIONS - blank at total level (set in the segment tabs)
B6: Gross store openings (number of stores) | N6: # stores | O6: n/a - segment-level assumption
B7: Store closures (number of stores) | N7: # stores | O7: n/a - segment-level assumption
B8: Same-store sales growth (applied to merchandise sales per average store) | N8: % p.a. | O8: n/a - segment-level assumption
B9: E-commerce merchandise sales growth | N9: % p.a. | O9: n/a - segment-level assumption
B10: Services attach rate (services revenue as % of merchandise sales) | N10: % of merch. | O10: n/a - segment-level assumption
B11: Other (non-retail / diamond sourcing) revenue growth | N11: % p.a. | O11: n/a - segment-level assumption
B12: Cost of sales (incl. store occupancy) as % of total sales | N12: % of sales | O12: n/a - segment-level assumption
B13: Variable SG&A (store payroll, advertising, credit) as % of total sales | N13: % of sales | O13: n/a - segment-level assumption
B14: Fixed SG&A inflation (corporate, support, fixed store overhead) | N14: % p.a. | O14: n/a - segment-level assumption
B15: Cost-savings initiatives (incremental run-rate cut to fixed SG&A) | N15: $M | O15: n/a - segment-level assumption
B16: Other operating income / (expense), one-time items (+ = income) | N16: $M | O16: n/a - segment-level assumption
B17: Net yield on invested assets (cash & equivalents) | N17: % of prior-yr cash | O17: n/a - segment-level assumption
... B20: Discount rate (cost of equity, CAPM) - single rate for the segment | N20: % p.a. | O20: n/a - segment-level assumption
A22: SHOCK TO ASSUMPTIONS - blank at total level
B23: Gross store openings (number of stores) | N23: # stores | O23: n/a - segment-level assumption
B24: Store closures (number of stores) | N24: # stores | O24: n/a - segment-level assumption
B25: Same-store sales growth (applied to merchandise sales per average store) | N25: % p.a. | O25: n/a - segment-level assumption
B26: E-commerce merchandise sales growth | N26: % p.a. | O26: n/a - segment-level assumption
B27: Services attach rate (services revenue as % of merchandise sales) | N27: % of merch. | O27: n/a - segment-level assumption
B28: Other (non-retail / diamond sourcing) revenue growth | N28: % p.a. | O28: n/a - segment-level assumption
B29: Cost of sales (incl. store occupancy) as % of total sales | N29: % of sales | O29: n/a - segment-level assumption
B30: Variable SG&A (store payroll, advertising, credit) as % of total sales | N30: % of sales | O30: n/a - segment-level assumption
B31: Fixed SG&A inflation (corporate, support, fixed store overhead) | N31: % p.a. | O31: n/a - segment-level assumption
B32: Cost-savings initiatives (incremental run-rate cut to fixed SG&A) | N32: $M | O32: n/a - segment-level assumption
B33: Other operating income / (expense), one-time items (+ = income) | N33: $M | O33: n/a - segment-level assumption
B34: Net yield on invested assets (cash & equivalents) | N34: % of prior-yr cash | O34: n/a - segment-level assumption
... B37: Discount rate (cost of equity, CAPM) - single rate for the segment | N37: % p.a. | O37: n/a - segment-level assumption
A39: ASSUMPTIONS FOR SCENARIO RUN - blank at total level
B40: Gross store openings (number of stores) | N40: # stores | O40: n/a - segment-level assumption
B41: Store closures (number of stores) | N41: # stores | O41: n/a - segment-level assumption
B42: Same-store sales growth (applied to merchandise sales per average store) | N42: % p.a. | O42: n/a - segment-level assumption
B43: E-commerce merchandise sales growth | N43: % p.a. | O43: n/a - segment-level assumption
B44: Services attach rate (services revenue as % of merchandise sales) | N44: % of merch. | O44: n/a - segment-level assumption
B45: Other (non-retail / diamond sourcing) revenue growth | N45: % p.a. | O45: n/a - segment-level assumption
B46: Cost of sales (incl. store occupancy) as % of total sales | N46: % of sales | O46: n/a - segment-level assumption
B47: Variable SG&A (store payroll, advertising, credit) as % of total sales | N47: % of sales | O47: n/a - segment-level assumption
...

Sheet Summary & Chart
A1: Signet Jewelers - Baseline Company Value by Business Segment
A2: $ millions. Values are links to the model tabs (green). Charts are native Excel charts linked to the cells below.
B4: Business segment | C4: Baseline value ($M) | D4: % of total | E4: Discount rate | F4: FY2026A sales ($M) | G4: FY2027E net income ($M)
B5: North America | C5: ='Model - NA'!C98 -> 3452.22 | D5: =IF($C$8=0,0,C5/$C$8) -> 1.0472316 | E5: ='Model - NA'!C94 -> 0.105 | F5: ='Model - NA'!C70 -> 6363.6 | G5: ='Model - NA'!D87 -> 461.00164
B6: International | C6: ='Model - INTL'!C98 -> 107.66 | D6: =IF($C$8=0,0,C6/$C$8) -> 0.032658682 | E6: ='Model - INTL'!C94 -> 0.12 | F6: ='Model - INTL'!C70 -> 410.4 | G6: ='Model - INTL'!D87 -> 12.996147
B7: Other / Corporate | C7: ='Model - OTHER'!C98 -> -263.36 | D7: =IF($C$8=0,0,C7/$C$8) -> -0.079890309 | E7: ='Model - OTHER'!C94 -> 0.105 | F7: ='Model - OTHER'!C70 -> 39.6 | G7: ='Model - OTHER'!D87 -> -41.141034
B8: Total company (sum of segments) | C8: =SUM(C5:C7) -> 3296.52 | D8: =SUM(D5:D7) -> 1 | F8: =SUM(F5:F7) -> 6813.6 | G8: =SUM(G5:G7) -> 432.85675
B9: Market capitalization (Oct 9, 2026; $105.22 x 37.5M shares) | C9: ='Total Company'!C124 -> 3945.75
B10: Model value / market cap - 1 | C10: ='Total Company'!C126 -> -0.16453906
B11: Model value per share ($) | C11: ='Total Company'!C127 -> 87.9072
B13: Projected total company sales and net income by year ($M; links to Total Company tab)
B14: Fiscal year | C14: FY2026A | D14: FY2027 | E14: FY2028 | F14: FY2029 | G14: FY2030 | H14: FY2031 | I14: FY2032 | J14: FY2033 | K14: FY2034 | L14: FY2035 | M14: FY2036
B15: Total sales | C15: ='Total Company'!C70 -> 6813.6 | D15: ='Total Company'!D70 -> 6831.5259 | E15: ='Total Company'!E70 -> 6901.313 | F15: ='Total Company'!F70 -> 6995.8046 | G15: ='Total Company'!G70 -> 7116.0016 | H15: ='Total Company'!H70 -> 7257.8424 | I15: ='Total Company'!I70 -> 7415.3587 | J15: ='Total Company'!J70 -> 7583.6084 | ... M15: ='Total Company'!M70 -> 8116.4726
B16: Net income | C16: ='Total Company'!C87 -> 294.4 | D16: ='Total Company'!D87 -> 432.85675 | E16: ='Total Company'!E87 -> 405.69194 | F16: ='Total Company'!F87 -> 406.34051 | G16: ='Total Company'!G87 -> 411.37817 | H16: ='Total Company'!H87 -> 419.54527 | I16: ='Total Company'!I87 -> 429.87518 | J16: ='Total Company'!J87 -> 441.58348 | ... M16: ='Total Company'!M87 -> 479.34304
B17: Operating income | C17: ='Total Company'!C80 -> 393.1 | D17: ='Total Company'!D80 -> 563.65276 | E17: ='Total Company'!E80 -> 527.90443 | F17: ='Total Company'!F80 -> 528.75436 | G17: ='Total Company'!G80 -> 535.37919 | H17: ='Total Company'!H80 -> 546.1215 | I17: ='Total Company'!I80 -> 559.71105 | J17: ='Total Company'!J80 -> 575.11582 | ... M17: ='Total Company'!M80 -> 624.79617
B21: Sensitivity of total company baseline value (computed by re-running the model with build/build_model.py; pasted values)
B22: Assumption shocked (all years, all segments unless stated) | C22: Value: -1pp / less ($M) | D22: Base ($M) | E22: Value: +1pp / more ($M) | F22: Change for +1pp ($M) | G22: Change for +1pp (%)
B23: Revenue growth: same-store, e-commerce and other revenue growth +/-1pp | C23: 2985.6 | D23: 3296.5 | E23: 3624.6 | F23: =E23-D23 -> 328.1 | G23: =IF(D23=0,0,E23/D23-1) -> 0.099529804
B24: Gross margin +/-1pp (cost of sales % -/+1pp) | C24: 2965.5 | D24: 3296.5 | E24: 3627.6 | F24: =E24-D24 -> 331.1 | G24: =IF(D24=0,0,E24/D24-1) -> 0.10043986
B25: Discount rate (cost of equity) +/-1pp | C25: 3480.7 | D25: 3296.5 | E25: 3126.4 | F25: =E25-D25 -> -170.1 | G25: =IF(D25=0,0,E25/D25-1) -> -0.051600182
B26: Variable SG&A % of sales +/-1pp | C26: 3627.6 | D26: 3296.5 | E26: 2965.5 | F26: =E26-D26 -> -331 | G26: =IF(D26=0,0,E26/D26-1) -> -0.10040953
B27: Fixed SG&A inflation +/-1pp | C27: 3491.8 | D27: 3296.5 | E27: 3090.5 | F27: =E27-D27 -> -206 | G27: =IF(D27=0,0,E27/D27-1) -> -0.06249052
B28: Effective tax rate +/-1pp | C28: 3330.5 | D28: 3296.5 | E28: 3262.6 | F28: =E28-D28 -> -33.9 | G28: =IF(D28=0,0,E28/D28-1) -> -0.010283634
B29: NA store closures +/-10 per year | C29: 3387.6 | D29: 3296.5 | E29: 3205.5 | F29: =E29-D29 -> -91 | G29: =IF(D29=0,0,E29/D29-1) -> -0.027605036

Sheet Checks
A1: Model integrity checks (formula-driven; every row must be TRUE)
A2: Tolerances: $0.05M for ties to reported figures, $0.001M for internal identities.
A4: # | B4: Check | C4: Result | D4: Measured value | E4: Tolerance / target
A5: 1 | B5: Total Company sales = NA + INTL + OTHER in every year (FY2026A-FY2036) | C5: =SUMPRODUCT(ABS('Total Company'!C70:M70-'Model - NA'!C70:M70-'Model - INTL'!C70:M70-'Model - OTHER'!C70:M70))<0.001 -> TRUE | D5: =SUMPRODUCT(ABS('Total Company'!C70:M70-'Model - NA'!C70:M70-'Model - INTL'!C70:M70-'Model - OTHER'!C70:M70)) -> 4.206413e-12 | E5: < 0.001
A6: 2 | B6: Total Company operating income = NA + INTL + OTHER in every year (FY2026A-FY2036) | C6: =SUMPRODUCT(ABS('Total Company'!C80:M80-'Model - NA'!C80:M80-'Model - INTL'!C80:M80-'Model - OTHER'!C80:M80))<0.001 -> TRUE | D6: =SUMPRODUCT(ABS('Total Company'!C80:M80-'Model - NA'!C80:M80-'Model - INTL'!C80:M80-'Model - OTHER'!C80:M80)) -> 6.2030381e-12 | E6: < 0.001
A7: 3 | B7: Total Company net income = NA + INTL + OTHER in every year (FY2026A-FY2036) | C7: =SUMPRODUCT(ABS('Total Company'!C87:M87-'Model - NA'!C87:M87-'Model - INTL'!C87:M87-'Model - OTHER'!C87:M87))<0.001 -> TRUE | D7: =SUMPRODUCT(ABS('Total Company'!C87:M87-'Model - NA'!C87:M87-'Model - INTL'!C87:M87-'Model - OTHER'!C87:M87)) -> 6.6862071e-12 | E7: < 0.001
A8: 4 | B8: Total Company shareholders' equity = NA + INTL + OTHER in every year (FY2026A-FY2036) | C8: =SUMPRODUCT(ABS('Total Company'!C110:M110-'Model - NA'!C110:M110-'Model - INTL'!C110:M110-'Model - OTHER'!C110:M110))<0.001 -> TRUE | D8: =SUMPRODUCT(ABS('Total Company'!C110:M110-'Model - NA'!C110:M110-'Model - INTL'!C110:M110-'Model - OTHER'!C110:M110)) -> 7.2297723e-13 | E8: < 0.001
A9: 5 | B9: Total Company cash = NA + INTL + OTHER in every year (FY2026A-FY2036) | C9: =SUMPRODUCT(ABS('Total Company'!C104:M104-'Model - NA'!C104:M104-'Model - INTL'!C104:M104-'Model - OTHER'!C104:M104))<0.001 -> TRUE | D9: =SUMPRODUCT(ABS('Total Company'!C104:M104-'Model - NA'!C104:M104-'Model - INTL'!C104:M104-'Model - OTHER'!C104:M104)) -> 7.2297723e-13 | E9: < 0.001
A10: 6 | B10: FY2026A consolidated sales reproduces reported 6,813.6 | C10: =ABS('Total Company'!C70-6813.6)<0.05 -> TRUE | D10: ='Total Company'!C70 -> 6813.6 | E10: 6,813.6 +/- 0.05
A11: 7 | B11: FY2026A consolidated operating income reproduces reported 393.1 | C11: =ABS('Total Company'!C80-393.1)<0.05 -> TRUE | D11: ='Total Company'!C80 -> 393.1 | E11: 393.1 +/- 0.05
A12: 8 | B12: FY2026A consolidated net income reproduces reported 294.4 | C12: =ABS('Total Company'!C87-294.4)<0.05 -> TRUE | D12: ='Total Company'!C87 -> 294.4 | E12: 294.4 +/- 0.05
A13: 9 | B13: FY2026A shareholders' equity reproduces reported 1,966.2 | C13: =ABS('Total Company'!C110-1966.2)<0.05 -> TRUE | D13: ='Total Company'!C110 -> 1966.2 | E13: 1,966.2 +/- 0.05
A14: 10 | B14: FY2026A North America sales = reported 6,363.6 | C14: =ABS('Model - NA'!C70-6363.6)<0.05 -> TRUE | D14: ='Model - NA'!C70 -> 6363.6 | E14: 6,363.6
A15: 11 | B15: FY2026A North America operating income = reported 452.6 | C15: =ABS('Model - NA'!C80-452.6)<0.05 -> TRUE | D15: ='Model - NA'!C80 -> 452.6 | E15: 452.6
A16: 12 | B16: FY2026A International sales = reported 410.4 | C16: =ABS('Model - INTL'!C70-410.4)<0.05 -> TRUE | D16: ='Model - INTL'!C70 -> 410.4 | E16: 410.4
A17: 13 | B17: FY2026A International operating income = reported 16.3 | C17: =ABS('Model - INTL'!C80-16.3)<0.05 -> TRUE | D17: ='Model - INTL'!C80 -> 16.3 | E17: 16.3
A18: 14 | B18: FY2026A Other / Corporate sales = reported 39.6 | C18: =ABS('Model - OTHER'!C70-39.6)<0.05 -> TRUE | D18: ='Model - OTHER'!C70 -> 39.6 | E18: 39.6
A19: 15 | B19: FY2026A Other / Corporate operating income = reported -75.8 | C19: =ABS('Model - OTHER'!C80--75.8)<0.05 -> TRUE | D19: ='Model - OTHER'!C80 -> -75.8 | E19: -75.8
A20: 16 | B20: Balance sheet balances (assets = liabilities + equity) every year in every tab | C20: =SUMPRODUCT(ABS('Model - NA'!C112:M112))+SUMPRODUCT(ABS('Model - INTL'!C112:M112))+SUMPRODUCT(ABS('Model - OTHER'!C112:M112))+SUMPRODUCT(ABS('Total Company'!C112:M112))<0.001 -> TRUE | D20: =SUMPRODUCT(ABS('Model - NA'!C112:M112))+SUMPRODUCT(ABS('Model - INTL'!C112:M112))+SUMPRODUCT(ABS('Model - OTHER'!C112:M112))+SUMPRODUCT(ABS('Total Company'!C112:M112)) -> 0 | E20: < 0.001
A21: 17 | B21: Equity roll-forward Equity(t) = Equity(t-1) + NI(t) - Distributions(t) holds every year in every tab | C21: =SUMPRODUCT(ABS('Model - NA'!D111:M111))+SUMPRODUCT(ABS('Model - INTL'!D111:M111))+SUMPRODUCT(ABS('Model - OTHER'!D111:M111))+SUMPRODUCT(ABS('Total Company'!D111:M111))<0.001 -> TRUE | D21: =SUMPRODUCT(ABS('Model - NA'!D111:M111))+SUMPRODUCT(ABS('Model - INTL'!D111:M111))+SUMPRODUCT(ABS('Model - OTHER'!D111:M111))+SUMPRODUCT(ABS('Total Company'!D111:M111)) -> 0 | E21: < 0.001
A22: 18 | B22: North America: scenario assumptions = baseline + shock for every cell | C22: =SUMPRODUCT(ABS('Model - NA'!D40:M54-'Model - NA'!D6:M20-'Model - NA'!D23:M37))<0.0000001 -> TRUE | D22: =SUMPRODUCT(ABS('Model - NA'!D40:M54-'Model - NA'!D6:M20-'Model - NA'!D23:M37)) -> 0 | E22: < 1e-7
A23: 19 | B23: North America: all shock cells are zero (baseline run) | C23: =SUMPRODUCT(ABS('Model - NA'!D23:M37))=0 -> TRUE | D23: =SUMPRODUCT(ABS('Model - NA'!D23:M37)) -> 0 | E23: 0
A24: 20 | B24: International: scenario assumptions = baseline + shock for every cell | C24: =SUMPRODUCT(ABS('Model - INTL'!D40:M54-'Model - INTL'!D6:M20-'Model - INTL'!D23:M37))<0.0000001 -> TRUE | D24: =SUMPRODUCT(ABS('Model - INTL'!D40:M54-'Model - INTL'!D6:M20-'Model - INTL'!D23:M37)) -> 0 | E24: < 1e-7
A25: 21 | B25: International: all shock cells are zero (baseline run) | C25: =SUMPRODUCT(ABS('Model - INTL'!D23:M37))=0 -> TRUE | D25: =SUMPRODUCT(ABS('Model - INTL'!D23:M37)) -> 0 | E25: 0
A26: 22 | B26: Other / Corporate: scenario assumptions = baseline + shock for every cell | C26: =SUMPRODUCT(ABS('Model - OTHER'!D40:M54-'Model - OTHER'!D6:M20-'Model - OTHER'!D23:M37))<0.0000001 -> TRUE | D26: =SUMPRODUCT(ABS('Model - OTHER'!D40:M54-'Model - OTHER'!D6:M20-'Model - OTHER'!D23:M37)) -> 0 | E26: < 1e-7
A27: 23 | B27: Other / Corporate: all shock cells are zero (baseline run) | C27: =SUMPRODUCT(ABS('Model - OTHER'!D23:M37))=0 -> TRUE | D27: =SUMPRODUCT(ABS('Model - OTHER'!D23:M37)) -> 0 | E27: 0
